<?xml version="1.0"?>
<robot name="grass_hopper" xmlns:xacro="http://ros.org/wiki/xacro">

  <material name="black">
      <color rgba="0.0 0.0 0.0 1.0"/>
  </material>

  <material name="dark">
    <color rgba="0.3 0.3 0.3 1.0"/>
  </material>

  <material name="light_black">
    <color rgba="0.4 0.4 0.4 1.0"/>
  </material>

  <material name="blue">
    <color rgba="0.0 0.0 0.8 1.0"/>
  </material>

  <material name="green">
    <color rgba="0.0 0.8 0.0 1.0"/>
  </material>

  <material name="grey">
    <color rgba="0.5 0.5 0.5 1.0"/>
  </material>

  <material name="orange">
    <color rgba="1.0 0.4235 0.0392 1.0"/>
  </material>

  <material name="brown">
    <color rgba="0.8706 0.8118 0.7647 1.0"/>
  </material>

  <material name="red">
    <color rgba="0.8 0.0 0.0 1.0"/>
  </material>

  <material name="white">
    <color rgba="1.0 1.0 1.0 1.0"/>
  </material>

  <link name="base_footprint"/>

  <joint name="base_footprint_to_base_link" type="fixed">
    <parent link="base_footprint" />
    <child link="base_link" />
    <origin xyz="0 0 0.075"/>
  </joint>

  <link name="base_link">
    <visual>
      <origin xyz="0 0 0" rpy="0 0 0" />
      <geometry>
        <mesh filename="file:///home/dhaval_lad/dhaval_ws/src/grasshopper_description/meshes/base_link.stl" />
      </geometry>
      <material name="grey"/>
    </visual>

    <collision>
      <origin xyz="0 0 0.081" rpy="0 0 0" />
      <geometry>
        <box size="0.6 0.269 0.17"/>
      </geometry>
    </collision>

    <inertial>
      <origin xyz="0 0 0.05" rpy="0 0 0" />
      <mass value="25" />
      <!-- <inertia ixx="0.2109604" ixy="0" ixz="0" iyy="0.8102083" iyz="0" izz="0.90075208" /> -->25kg
      <inertia ixx="0.2109604" ixy="0" ixz="0" iyy="0.5502083" iyz="0" izz="0.7575208" />
    </inertial>
  </link>

  <gazebo reference="base_link">  
    <visual>  
      <material>
        <ambient>0.4 0.4 0.4 1.0</ambient>  
        <diffuse>0.4 0.4 0.4 1.0</diffuse>   
        <specular>0.99 0.99 0.99 1.0</specular>  
        <emissive>0.0 0.0 0.0 0.0</emissive>  
      </material>
    </visual> 
  </gazebo>

  <link name="upper_base_link">
    <visual>
      <origin xyz="-0.3 -0.1325 0" rpy="1.57 0 1.57" />
      <geometry>
        <mesh filename="file:///home/dhaval_lad/dhaval_ws/src/grasshopper_description/meshes/upper_base_link.stl" scale="0.001 0.001 0.001" />
      </geometry>
      <material name="grey"/>
    </visual>

    <collision>
      <origin xyz="-0.3 -0.1325 0" rpy="1.57 0 1.57" />
      <geometry>
        <mesh filename="file:///home/dhaval_lad/dhaval_ws/src/grasshopper_description/meshes/upper_base_link.stl" scale="0.001 0.001 0.001" />
      </geometry>
    </collision>

    <inertial>
      <origin xyz="0 0 0" rpy="0 0 0" />
      <mass value="1" />
      <inertia ixx="8.438416e-3" ixy="0" ixz="0" iyy="0.0324083" iyz="0" izz="0.03603008" />
    </inertial>
  </link>

  <gazebo reference="upper_base_link">  
    <visual>  
      <material>
        <ambient>0.75 0.75 0.75 1.0</ambient>  
        <diffuse>0.75 0.75 0.75 1.0</diffuse>  
        <specular>0.99 0.99 0.99 1.0</specular>  
        <emissive>0.0 0.0 0.0 0.0</emissive>  
      </material>
    </visual> 
  </gazebo>

  <joint name="base_link_to_upper_base_link" type="fixed">
    <parent link="base_link" />
    <child link="upper_base_link" />
    <origin xyz="0 0 0.165"/>
  </joint>

  <link name="left_front_wheel">
    <visual>
      <origin xyz="0 0.04 0" rpy="1.57 0 0" />
      <geometry>
        <mesh filename="file:///home/dhaval_lad/dhaval_ws/src/grasshopper_description/meshes/left_front_wheel.stl" />
      </geometry>
      <material name="blue"/>
    </visual>

    <collision>
      <origin xyz="0 0.04 0" rpy="1.57 0 0" />
      <geometry>
        <mesh filename="file:///home/dhaval_lad/dhaval_ws/src/grasshopper_description/meshes/left_front_wheel.stl" />
      </geometry>
    </collision>

    <inertial>
      <origin xyz="0 0 0" rpy="0 0 0" />
      <mass value="0.7" />
      <!-- <inertia ixx="2.53229e-3" ixy="0" ixz="0" iyy="2.53229e-3" iyz="0" izz="4.53125e-4" /> -->0.5kg
      <inertia ixx="3.545208e-3" ixy="0" ixz="0" iyy="3.545208e-3" iyz="0" izz="6.34375e-3" />
    </inertial>
  </link>

  <gazebo reference="left_front_wheel">
    <mu1>0.8</mu1>
    <mu2>0.7</mu2>   
    <visual>  
      <material>
        <ambient>0.1764 0.4588 0.8509 1.0</ambient>  
        <diffuse>0.1764 0.4588 0.8509 1.0</diffuse>  
        <specular>0.1764 0.4588 0.8509 1.0</specular>  
        <emissive>0.0 0.0 0.0 0.0</emissive>  
      </material>
    </visual>  
  </gazebo>

  <joint name="base_link_to_left_front_wheel" type="continuous">
    <origin xyz="0.1483 0.1745 0.05" rpy="0 0 0" />
    <parent link="base_link" />
    <child link="left_front_wheel" />
    <axis xyz="0 1 0" />
  </joint>

  <link name="right_front_wheel">
    <visual>
      <origin xyz="0 -0.04 0" rpy="1.57 0 0" />
      <geometry>
        <mesh filename="file:///home/dhaval_lad/dhaval_ws/src/grasshopper_description/meshes/right_front_wheel.stl" />
      </geometry>
      <material name="blue"/>
    </visual>
    
    <collision>
      <origin xyz="0 -0.04 0" rpy="1.57 0 0" />
      <geometry>
        <mesh filename="file:///home/dhaval_lad/dhaval_ws/src/grasshopper_description/meshes/right_front_wheel.stl" />
      </geometry>
    </collision>

    <inertial>
      <origin xyz="0 0 0" rpy="0 0 0" />
      <mass value="0.7" />
      <!-- <inertia ixx="2.53229e-3" ixy="0" ixz="0" iyy="2.53229e-3" iyz="0" izz="4.53125e-4" /> -->0.5kg
      <inertia ixx="3.545208e-3" ixy="0" ixz="0" iyy="3.545208e-3" iyz="0" izz="6.34375e-3" />
    </inertial>
  </link>

  <gazebo reference="right_front_wheel"> 
    <mu1>0.8</mu1>
    <mu2>0.7</mu2>  
    <visual>  
      <material>
        <ambient>0.1764 0.4588 0.8509 1.0</ambient>  
        <diffuse>0.1764 0.4588 0.8509 1.0</diffuse>  
        <specular>0.1764 0.4588 0.8509 1.0</specular>  
        <emissive>0.0 0.0 0.0 0.0</emissive>  
      </material>
    </visual>  
  </gazebo>

  <joint name="base_link_to_right_front_wheel" type="continuous">
    <origin xyz="0.1483 -0.1745 0.05" rpy="0 0 0" />
    <parent link="base_link" />
    <child link="right_front_wheel" />
    <axis xyz="0 1 0" />
  </joint>

  <link name="left_rear_wheel">
    <visual>
      <origin xyz="0 0.04 0" rpy="1.57 0 0" />
      <geometry>
        <mesh filename="file:///home/dhaval_lad/dhaval_ws/src/grasshopper_description/meshes/left_rear_wheel.stl" />
      </geometry>
      <material name="blue"/>
    </visual>

    <collision>
      <origin xyz="0 0.04 0" rpy="1.57 0 0" />
      <geometry>
        <mesh filename="file:///home/dhaval_lad/dhaval_ws/src/grasshopper_description/meshes/left_rear_wheel.stl" />
      </geometry>
    </collision>

    <inertial>
      <origin xyz="0 0 0" rpy="0 0 0" />
      <mass value="0.7" />
      <!-- <inertia ixx="2.53229e-3" ixy="0" ixz="0" iyy="2.53229e-3" iyz="0" izz="4.53125e-4" /> -->0.5kg
      <inertia ixx="3.545208e-3" ixy="0" ixz="0" iyy="3.545208e-3" iyz="0" izz="6.34375e-3" />
    </inertial>
  </link>

  <gazebo reference="left_rear_wheel"> 
    <mu1>0.8</mu1>
    <mu2>0.7</mu2>  
    <visual>  
      <material>
        <ambient>0.1764 0.4588 0.8509 1.0</ambient>  
        <diffuse>0.1764 0.4588 0.8509 1.0</diffuse>  
        <specular>0.1764 0.4588 0.8509 1.0</specular>  
        <emissive>0.0 0.0 0.0 0.0</emissive>  
      </material>
    </visual>  
  </gazebo>
    
  <joint name="base_link_to_left_rear_wheel" type="continuous">
    <origin xyz="-0.1483 0.1745 0.05" rpy="0 0 0" />
    <parent link="base_link" />
    <child link="left_rear_wheel" />
    <axis xyz="0 1 0" />
  </joint>

  <link name="right_rear_wheel">
    <visual>
      <origin xyz="0 -0.04 0" rpy="1.57 0 0" />
      <geometry>
        <mesh filename="file:///home/dhaval_lad/dhaval_ws/src/grasshopper_description/meshes/right_rear_wheel.stl" />
      </geometry>
      <material name="blue"/>
    </visual>

    <collision>
      <origin xyz="0 -0.04 0" rpy="1.57 0 0" />
      <geometry>
        <mesh filename="file:///home/dhaval_lad/dhaval_ws/src/grasshopper_description/meshes/right_rear_wheel.stl" />
      </geometry>
    </collision>

    <inertial>
      <origin xyz="0 0 0" rpy="0 0 0" />
      <mass value="0.7" />
      <!-- <inertia ixx="2.53229e-3" ixy="0" ixz="0" iyy="2.53229e-3" iyz="0" izz="4.53125e-4" /> -->0.5kg
      <inertia ixx="3.545208e-3" ixy="0" ixz="0" iyy="3.545208e-3" iyz="0" izz="6.34375e-3" />
    </inertial>
  </link>

  <gazebo reference="right_rear_wheel"> 
    <mu1>0.8</mu1>
    <mu2>0.7</mu2> 
    <visual>  
      <material>
        <ambient>0.1764 0.4588 0.8509 1.0</ambient>  
        <diffuse>0.1764 0.4588 0.8509 1.0</diffuse>  
        <specular>0.1764 0.4588 0.8509 1.0</specular>  
        <emissive>0.0 0.0 0.0 0.0</emissive>  
      </material>
    </visual>  
  </gazebo>

  <joint name="base_link_to_right_rear_wheel" type="continuous">
    <origin xyz="-0.1483 -0.1745 0.05" rpy="0 0 0" />
    <parent link="base_link" />
    <child link="right_rear_wheel" />
    <axis xyz="0 1 0" />
  </joint>

  <gazebo>
    <plugin name="diff_drive" filename="libgazebo_ros_diff_drive.so">
      <!-- <ros>
        <remapping>odom:=odom/unfiltered</remapping> 0,429
      </ros> -->

      <num_wheel_pairs>2</num_wheel_pairs>
      <left_joint>base_link_to_left_front_wheel</left_joint>
      <right_joint>base_link_to_right_front_wheel</right_joint>
      <left_joint>base_link_to_left_rear_wheel</left_joint>
      <right_joint>base_link_to_right_rear_wheel</right_joint>

      <wheel_separation>0.349</wheel_separation>
      <wheel_separation>0.349</wheel_separation>
      <wheel_diameter>0.25</wheel_diameter>
      <wheel_diameter>0.25</wheel_diameter>

      <update_rate>50</update_rate>
      <max_wheel_torque>20</max_wheel_torque>
      <max_wheel_velocity>80</max_wheel_velocity>
      <wheel_torque_limit>15</wheel_torque_limit>
      <max_wheel_acceleration>1</max_wheel_acceleration>
      <robot_base_frame>base_footprint</robot_base_frame>
      <publish_odom>true</publish_odom>
      <publish_odom_tf>true</publish_odom_tf>
      <publish_wheel_tf>true</publish_wheel_tf>
      <odometry_frame>odom</odometry_frame>

    </plugin>
  </gazebo>

  <link name="laser">
    <visual>
      <origin xyz="0 0 -0.025" rpy="0 0 0"/>
      <geometry>
        <cylinder radius="0.0375" length="0.05"/>
      </geometry>
      <material name="green"/>
    </visual>
    <collision>
      <origin xyz="0 0 -0.025" rpy="0 0 0"/>
      <geometry>
        <cylinder radius="0.0375" length="0.05"/>
      </geometry>
    </collision>

    <inertial>
      <origin xyz="0 0 0" rpy="0 0 0"/>
      <mass value="0.2"/>
      <inertia ixx="1.1197916e-4" ixy="0" ixz="0"
                iyy="1.1197916e-4" iyz="0"
                izz="1.40625e-4" />
    </inertial>
  </link>

  <gazebo reference="laser">  
    <visual>  
      <material>
        <ambient>0.003 0.639 0.223 1.0</ambient>  
        <diffuse>0.003 0.639 0.223 1.0</diffuse>  
        <specular>0.003 0.639 0.223 1.0</specular>  
        <emissive>0.0 0.0 0.0 0.0</emissive>  
      </material>
    </visual> 
  </gazebo>

  <joint name="base_link_to_laser" type="fixed">
    <parent link="base_link"/>
    <child link="laser"/>
    <!-- <origin xyz="0.263 0 0.245" rpy="0 0 0" />  -->   <!-- without upper base -->
    <origin xyz="0 0 0.48" rpy="0 0 0" />   <!-- with upper base -->
  </joint>

  <gazebo reference="laser">
    <sensor type="ray" name="laser_lidar">
      <always_on>true</always_on>
      <update_rate>15</update_rate>
      <pose>0 0 0 0 0 0</pose>
      <visualize>true</visualize>
      <ray>
        <scan>
          <horizontal>
            <samples>270</samples>
            <resolution>1</resolution>
            <min_angle>-1.5708</min_angle>
            <max_angle>3.1415926</max_angle>
          </horizontal>
        </scan>
        <range>
          <min>0.08</min>
          <max>10.0</max>
          <resolution>0.01</resolution>
        </range>
      </ray>
      <plugin name="laser" filename="libgazebo_ros_ray_sensor.so">
        <ros>
          <remapping>~/out:=scan</remapping>                                                                                                                           
        </ros>
        <output_type>sensor_msgs/LaserScan</output_type>
        <alwaysOn>true</alwaysOn>
        <updateRate>15</updateRate>
        <topicName>scan</topicName>
        <frame_name>laser</frame_name>
        <output_type>sensor_msgs/LaserScan</output_type>
      </plugin>
    </sensor>
  </gazebo>

  <link name="imu_link"/>

  <joint name="base_link_to_imu_link" type="fixed">
    <parent link="base_link"/>
    <child link="imu_link"/>
    <origin xyz="0 0 0.17" rpy="0 0 0"/>
  </joint>

  <gazebo reference="imu_link">
    <gravity>true</gravity>
    <sensor name="imu_sensor" type="imu">
    <always_on>true</always_on>
    <update_rate>100</update_rate>
    <visualize>true</visualize>
    <topic>__default_topic__</topic>
    <plugin filename="libgazebo_ros_imu_sensor.so" name="imu_plugin">
        <ros>
          <remapping>~/out:=imu/data</remapping>
        </ros>
        <topicName>imu/data</topicName>
        <bodyName>imu_link</bodyName>
        <gaussianNoise>0.0</gaussianNoise>
        <xyzOffset>0 0 0</xyzOffset>
        <rpyOffset>0 0 0</rpyOffset>
        <frameName>imu_link</frameName>
        <initialOrientationAsReference>false</initialOrientationAsReference>
    </plugin>
    <pose>0 0 0 0 0 0</pose>
    </sensor>
  </gazebo>

  <link name="camera_link">
    <visual>
      <origin xyz="0 0 0" rpy="0 0 0"/>
      <geometry>
        <box size="0.030 0.124 0.030"/>
        <!-- <mesh filename="" scale="0.001 0.001 0.001"/> -->
      </geometry>
      <material name="red"/>
    </visual>
    
    <collision>
      <origin xyz="0 0 0" rpy="0 0 0"/>
      <geometry>
        <box size="0.030 0.124 0.030"/>
      </geometry>
    </collision>

    <inertial>
      <origin xyz="0 0 0" rpy="0 0 0"/>
      <mass value="0.135"/>
      <inertia ixx="1.83105e-4" ixy="0.0" ixz="0.0"
                iyy="2.025e-5" iyz="0.0"
                izz="1.83105e-4"/>
    </inertial>
  </link>

  <joint name="camera_to_base_link" type="fixed">
    <parent link="base_link"/>
    <child link="camera_link"/>
    <origin xyz="0.315 0 0.155" rpy="0 0 0"/>
  </joint>

  <link name="camera_depth_link"/>
  <joint name="camera_depth_joint" type="fixed">
    <origin xyz="0 0 0" rpy="-1.57 0 -1.57"/>
    <parent link="camera_link"/>
    <child link="camera_depth_link"/>
  </joint>

  <gazebo reference="camera_link">
    <sensor name="camera" type="depth">
      <pose> 0 0 0 0 0 0 </pose>
      <visualization>true</visualization>
      <update_rate>50.0</update_rate>
      <camera>
        <horizontal_fov>1.50098</horizontal_fov>
        <image>
          <width>640</width>
          <height>480</height>
          <format>R8G8B8</format>
        </image>
        <clip>
          <near>0.05</near>
          <far>8.0</far>
        </clip>
      </camera>
        
      <plugin name="camera_controller" filename="libgazebo_ros_camera.so">
        <frame_name>camera_depth_link</frame_name>
        <min_depth>0.1</min_depth>
        <max_depth>100.0</max_depth>
      </plugin>
    </sensor>
  </gazebo>

  <gazebo reference="camera_link">  
    <visual>  
      <material>
        <ambient>0.8 0.0 0.0 1.0</ambient>  
        <diffuse>0.8 0.0 0.0 1.0</diffuse>  
        <specular>0.8 0.0 0.0 1.0</specular>  
        <emissive>0.0 0.0 0.0 0.0</emissive>  
      </material>
    </visual> 
  </gazebo>

</robot>